Workbook

Sheet BOM
B1: 日期 | C1: 客户 | D1: 料号 | E1: 产品规格 | F1: 使用材料 | G1: 原材料规格 | H1: 长度 | I1: 分切宽度 | J1: 小卷 | K1: 整支 | L1: 料头宽 | M1: 卷/支 | N1: 跳距 | O1: 穴数 | P1: 工单数 | Q1: 购买材料数量 （米） | R1: 购买材料数量 （平方）(5%) | S1: 模具编号 | T1: 单价 | U1: 原材料单价
B2: 44788 | C2: 米琦 | D2: 40*20空白标签 | E2: 40*20mm | F2: 50#合成纸（可移胶） | G2: =IFERROR(VLOOKUP(表1_3[[#This Row],[使用材料]],[1]材料清单!$D$2:$N$996,4,0),"") -> 1070 | H2: =IFERROR(VLOOKUP(表1_3[[#This Row],[使用材料]],[1]材料清单!$D$2:$N$996,5,0),"") -> 200 | I2: 45 | J2: =IFERROR(Q2/H2,"") -> 2.2 | K2: =IFERROR(J2/M2,"") -> 0.092523364 | L2: =(M2-INT(M2))*I2 -> 35 | M2: =G2/I2 -> 23.777778 | N2: 44 | O2: 2 | P2: 20000 | Q2: =P2*(N2/1000)/O2 -> 440 | R2: =Q2*I2/1000*1.05 -> 20.79 | S2: SD220808-00101A-02A-44 | U2: =IFERROR((VLOOKUP(F2,[1]材料清单!D2:K1996,6,0)),"") -> 4.5
F3: 白色格拉辛3-5GT=0.06MM | G3: =IFERROR(VLOOKUP(表1_3[[#This Row],[使用材料]],[1]材料清单!$D$2:$N$996,4,0),"") -> 1090 | H3: =IFERROR(VLOOKUP(表1_3[[#This Row],[使用材料]],[1]材料清单!$D$2:$N$996,5,0),"") -> 300 | I3: 50 | J3: =IFERROR(Q3/H3,"") -> 1.4666667 | K3: =IFERROR(J3/M3,"") -> 0.067278287 | L3: =(M3-INT(M3))*I3 -> 40 | M3: =G3/I3 -> 21.8 | N3: 44 | O3: 2 | P3: =P2 -> 20000 | Q3: =P3*(N3/1000)/O3 -> 440 | R3: =Q3*I3/1000*1.05 -> 23.1 | U3: =IFERROR((VLOOKUP(F3,[1]材料清单!D3:K1997,6,0)),"") -> 1.2
C4: 华云 | D4: 08-01-1638B-保护膜 | E4: 08-01-1638B-正面保护膜 (防静电） | F4: FU-500150AS | G4: =IFERROR(VLOOKUP(表1_3[[#This Row],[使用材料]],[1]材料清单!$D$2:$N$996,4,0),"") -> 1200 | H4: =IFERROR(VLOOKUP(表1_3[[#This Row],[使用材料]],[1]材料清单!$D$2:$N$996,5,0),"") -> 200 | I4: 171 | J4: =IFERROR(Q4/H4,"") -> 2.85525 | K4: =IFERROR(J4/M4,"") -> 0.40687313 | L4: =(M4-INT(M4))*I4 -> 3 | M4: =G4/I4 -> 7.0175439 | N4: 405 | O4: 1 | P4: 1410 | Q4: =P4*(N4/1000)/O4 -> 571.05 | R4: =Q4*I4/1000*1.05 -> 102.53203 | S4: 激光 | U4: =IFERROR((VLOOKUP(F4,[1]材料清单!D4:K1998,6,0)),"") -> 6.8
D5: 08-02-1638B-保护膜 | E5: 08-02-1638B-背面保护膜 (防静电） | F5: FU-500150AS | G5: =IFERROR(VLOOKUP(表1_3[[#This Row],[使用材料]],[1]材料清单!$D$2:$N$996,4,0),"") -> 1200 | H5: =IFERROR(VLOOKUP(表1_3[[#This Row],[使用材料]],[1]材料清单!$D$2:$N$996,5,0),"") -> 200 | I5: 147 | J5: =IFERROR(Q5/H5,"") -> 1.6074 | K5: =IFERROR(J5/M5,"") -> 0.1969065 | L5: =(M5-INT(M5))*I5 -> 24 | M5: =G5/I5 -> 8.1632653 | N5: 228 | O5: 1 | P5: 1410 | Q5: =P5*(N5/1000)/O5 -> 321.48 | R5: =Q5*I5/1000*1.05 -> 49.620438 | S5: 激光 | U5: =IFERROR((VLOOKUP(F5,[1]材料清单!D5:K1999,6,0)),"") -> 6.8
C6: 华云 | D6: 10-01-1638B-泡棉 | E6: 10-01-1638B-泡棉 | F6: PSR-10 | G6: =IFERROR(VLOOKUP(表1_3[[#This Row],[使用材料]],[1]材料清单!$D$2:$N$996,4,0),"") -> 520 | H6: =IFERROR(VLOOKUP(表1_3[[#This Row],[使用材料]],[1]材料清单!$D$2:$N$996,5,0),"") -> 100 | I6: 260 | J6: =IFERROR(Q6/H6,"") -> 0.6765 | K6: =IFERROR(J6/M6,"") -> 0.33825 | L6: =(M6-INT(M6))*I6 -> 0 | M6: =G6/I6 -> 2 | N6: 8.25 | O6: 1 | P6: 8200 | Q6: =IFERROR(P6*(N6/1000)/O6,"") -> 67.65 | R6: =IFERROR(Q6*I6/1000*1.05,"") -> 18.46845 | S6: 激光 | U6: =IFERROR((VLOOKUP(F6,[1]材料清单!D6:K2000,6,0)),"") -> 70
F7: 皇冠7972G-05 | G7: =IFERROR(VLOOKUP(表1_3[[#This Row],[使用材料]],[1]材料清单!$D$2:$N$996,4,0),"") -> 1240 | H7: =IFERROR(VLOOKUP(表1_3[[#This Row],[使用材料]],[1]材料清单!$D$2:$N$996,5,0),"") -> 100 | I7: 260 | J7: =IFERROR(Q7/H7,"") -> 0.6396 | K7: =IFERROR(J7/M7,"") -> 0.13410968 | L7: =(M7-INT(M7))*I7 -> 200 | M7: =G7/I7 -> 4.7692308 | N7: 7.8 | O7: 1 | P7: 8200 | Q7: =IFERROR(P7*(N7/1000)/O7,"") -> 63.96 | R7: =IFERROR(Q7*I7/1000*1.05,"") -> 17.46108 | S7: 激光 | U7: =IFERROR((VLOOKUP(F7,[1]材料清单!D7:K2001,6,0)),"") -> 6.8
C8: 华云 | D8: 10-02-1638B-泡棉 | E8: 10-02-1638B-泡棉 | F8: PSR-10 | G8: =IFERROR(VLOOKUP(表1_3[[#This Row],[使用材料]],[1]材料清单!$D$2:$N$996,4,0),"") -> 520 | H8: =IFERROR(VLOOKUP(表1_3[[#This Row],[使用材料]],[1]材料清单!$D$2:$N$996,5,0),"") -> 100 | I8: 260 | J8: =IFERROR(Q8/H8,"") -> 0.6396 | K8: =IFERROR(J8/M8,"") -> 0.3198 | L8: =(M8-INT(M8))*I8 -> 0 | M8: =G8/I8 -> 2 | N8: 7.8 | O8: 1 | P8: 8200 | Q8: =IFERROR(P8*(N8/1000)/O8,"") -> 63.96 | R8: =IFERROR(Q8*I8/1000*1.05,"") -> 17.46108 | U8: =IFERROR((VLOOKUP(F8,[1]材料清单!D8:K2002,6,0)),"") -> 70
F9: 皇冠7972G-05 | G9: =IFERROR(VLOOKUP(表1_3[[#This Row],[使用材料]],[1]材料清单!$D$2:$N$996,4,0),"") -> 1240 | H9: =IFERROR(VLOOKUP(表1_3[[#This Row],[使用材料]],[1]材料清单!$D$2:$N$996,5,0),"") -> 100 | I9: 260 | J9: =IFERROR(Q9/H9,"") -> 0.6396 | K9: =IFERROR(J9/M9,"") -> 0.13410968 | L9: =(M9-INT(M9))*I9 -> 200 | M9: =G9/I9 -> 4.7692308 | N9: 7.8 | O9: 1 | P9: 8200 | Q9: =IFERROR(P9*(N9/1000)/O9,"") -> 63.96 | R9: =IFERROR(Q9*I9/1000*1.05,"") -> 17.46108 | U9: =IFERROR((VLOOKUP(F9,[1]材料清单!D9:K2003,6,0)),"") -> 6.8
C10: 华云 | D10: 09-03-1638C-背胶 | E10: 09-03-1638C-背胶 | F10: 0.1蓝色离型膜30-40G | G10: =IFERROR(VLOOKUP(表1_3[[#This Row],[使用材料]],[1]材料清单!$D$2:$N$996,4,0),"") -> 1090 | H10: =IFERROR(VLOOKUP(表1_3[[#This Row],[使用材料]],[1]材料清单!$D$2:$N$996,5,0),"") -> 200 | I10: 183 | J10: =IFERROR(Q10/H10,"") -> 0.6345 | K10: =IFERROR(J10/M10,"") -> 0.10652615 | L10: =(M10-INT(M10))*I10 -> 175 | M10: =G10/I10 -> 5.9562842 | N10: 90 | O10: 1 | P10: 1410 | Q10: =P10*(N10/1000)/O10 -> 126.9 | R10: =Q10*I10/1000*1.05 -> 24.383835 | U10: =IFERROR((VLOOKUP(F10,[1]材料清单!D10:K2004,6,0)),"") -> 4.8
F11: 积水5240PSB | G11: =IFERROR(VLOOKUP(表1_3[[#This Row],[使用材料]],[1]材料清单!$D$2:$N$996,4,0),"") -> 980 | H11: =IFERROR(VLOOKUP(表1_3[[#This Row],[使用材料]],[1]材料清单!$D$2:$N$996,5,0),"") -> 50 | I11: 171 | J11: =IFERROR(Q11/H11,"") -> 2.538 | K11: =IFERROR(J11/M11,"") -> 0.4428551 | L11: =(M11-INT(M11))*I11 -> 125 | M11: =G11/I11 -> 5.7309942 | N11: 90 | O11: 1 | P11: 1410 | Q11: =P11*(N11/1000)/O11 -> 126.9 | R11: =Q11*I11/1000*1.05 -> 22.784895 | U11: =IFERROR((VLOOKUP(F11,[1]材料清单!D11:K2005,6,0)),"") -> 190
F12: 0.075mm 透明离型膜3-5g | G12: =IFERROR(VLOOKUP(表1_3[[#This Row],[使用材料]],[1]材料清单!$D$2:$N$996,4,0),"") -> 1090 | H12: =IFERROR(VLOOKUP(表1_3[[#This Row],[使用材料]],[1]材料清单!$D$2:$N$996,5,0),"") -> 200 | I12: 183 | J12: =IFERROR(Q12/H12,"") -> 0.6345 | K12: =IFERROR(J12/M12,"") -> 0.10652615 | L12: =(M12-INT(M12))*I12 -> 175 | M12: =G12/I12 -> 5.9562842 | N12: 90 | O12: 1 | P12: 1410 | Q12: =P12*(N12/1000)/O12 -> 126.9 | R12: =Q12*I12/1000*1.05 -> 24.383835 | U12: =IFERROR((VLOOKUP(F12,[1]材料清单!D12:K2006,6,0)),"") -> 3.5
C13: 华云 | D13: 09-04-1638B-背胶 | E13: 09-04-1638B-背胶 | F13: 0.1蓝色离型膜30-40G | G13: =IFERROR(VLOOKUP(表1_3[[#This Row],[使用材料]],[1]材料清单!$D$2:$N$996,4,0),"") -> 1090 | H13: =IFERROR(VLOOKUP(表1_3[[#This Row],[使用材料]],[1]材料清单!$D$2:$N$996,5,0),"") -> 200 | I13: 150 | J13: =IFERROR(Q13/H13,"") -> 0.12029062 | K13: =IFERROR(J13/M13,"") -> 0.016553756 | L13: =(M13-INT(M13))*I13 -> 40 | M13: =G13/I13 -> 7.2666667 | N13: 273 | O13: 16 | P13: 1410 | Q13: =P13*(N13/1000)/O13 -> 24.058125 | R13: =Q13*I13/1000*1.05 -> 3.7891547 | U13: =IFERROR((VLOOKUP(F13,[1]材料清单!D13:K2007,6,0)),"") -> 4.8
F14: 积水5240PSB | G14: =IFERROR(VLOOKUP(表1_3[[#This Row],[使用材料]],[1]材料清单!$D$2:$N$996,4,0),"") -> 980 | H14: =IFERROR(VLOOKUP(表1_3[[#This Row],[使用材料]],[1]材料清单!$D$2:$N$996,5,0),"") -> 50 | I14: 145 | J14: =IFERROR(Q14/H14,"") -> 0.4811625 | K14: =IFERROR(J14/M14,"") -> 0.071192411 | L14: =(M14-INT(M14))*I14 -> 110 | M14: =G14/I14 -> 6.7586207 | N14: 273 | O14: 16 | P14: 1410 | Q14: =P14*(N14/1000)/O14 -> 24.058125 | R14: =Q14*I14/1000*1.05 -> 3.6628495 | U14: =IFERROR((VLOOKUP(F14,[1]材料清单!D14:K2008,6,0)),"") -> 190
F15: 0.075mm 透明离型膜3-5g | G15: =IFERROR(VLOOKUP(表1_3[[#This Row],[使用材料]],[1]材料清单!$D$2:$N$996,4,0),"") -> 1090 | H15: =IFERROR(VLOOKUP(表1_3[[#This Row],[使用材料]],[1]材料清单!$D$2:$N$996,5,0),"") -> 200 | I15: 150 | J15: =IFERROR(Q15/H15,"") -> 0.12029062 | K15: =IFERROR(J15/M15,"") -> 0.016553756 | L15: =(M15-INT(M15))*I15 -> 40 | M15: =G15/I15 -> 7.2666667 | N15: 273 | O15: 16 | P15: 1410 | Q15: =P15*(N15/1000)/O15 -> 24.058125 | R15: =Q15*I15/1000*1.05 -> 3.7891547 | U15: =IFERROR((VLOOKUP(F15,[1]材料清单!D15:K2009,6,0)),"") -> 3.5
C16: 华云 | D16: 09-05-1638C-背胶 | E16: 09-05-1638C-背胶 | F16: 0.1蓝色离型膜30-40G | G16: =IFERROR(VLOOKUP(表1_3[[#This Row],[使用材料]],[1]材料清单!$D$2:$N$996,4,0),"") -> 1090 | H16: =IFERROR(VLOOKUP(表1_3[[#This Row],[使用材料]],[1]材料清单!$D$2:$N$996,5,0),"") -> 200 | I16: 183 | J16: =IFERROR(Q16/H16,"") -> 0.54285 | K16: =IFERROR(J16/M16,"") -> 0.091139037 | L16: =(M16-INT(M16))*I16 -> 175 | M16: =G16/I16 -> 5.9562842 | N16: 77 | O16: 1 | P16: 1410 | Q16: =P16*(N16/1000)/O16 -> 108.57 | R16: =Q16*I16/1000*1.05 -> 20.861725 | U16: =IFERROR((VLOOKUP(F16,[1]材料清单!D16:K2010,6,0)),"") -> 4.8
F17: 积水5240PSB | G17: =IFERROR(VLOOKUP(表1_3[[#This Row],[使用材料]],[1]材料清单!$D$2:$N$996,4,0),"") -> 980 | H17: =IFERROR(VLOOKUP(表1_3[[#This Row],[使用材料]],[1]材料清单!$D$2:$N$996,5,0),"") -> 50 | I17: 171 | J17: =IFERROR(Q17/H17,"") -> 2.1714 | K17: =IFERROR(J17/M17,"") -> 0.37888714 | L17: =(M17-INT(M17))*I17 -> 125 | M17: =G17/I17 -> 5.7309942 | N17: 77 | O17: 1 | P17: 1410 | Q17: =P17*(N17/1000)/O17 -> 108.57 | R17: =Q17*I17/1000*1.05 -> 19.493744 | U17: =IFERROR((VLOOKUP(F17,[1]材料清单!D17:K2011,6,0)),"") -> 190
F18: 0.075mm 透明离型膜3-5g | G18: =IFERROR(VLOOKUP(表1_3[[#This Row],[使用材料]],[1]材料清单!$D$2:$N$996,4,0),"") -> 1090 | H18: =IFERROR(VLOOKUP(表1_3[[#This Row],[使用材料]],[1]材料清单!$D$2:$N$996,5,0),"") -> 200 | I18: 183 | J18: =IFERROR(Q18/H18,"") -> 0.54285 | K18: =IFERROR(J18/M18,"") -> 0.091139037 | L18: =(M18-INT(M18))*I18 -> 175 | M18: =G18/I18 -> 5.9562842 | N18: 77 | O18: 1 | P18: 1410 | Q18: =P18*(N18/1000)/O18 -> 108.57 | R18: =Q18*I18/1000*1.05 -> 20.861725 | U18: =IFERROR((VLOOKUP(F18,[1]材料清单!D18:K2012,6,0)),"") -> 3.5
C20: 华云 | D20: 09-06-1638A-背胶 | E20: 09-06-1638A-背胶 | F20: 0.1蓝色离型膜30-40G | G20: =IFERROR(VLOOKUP(表1_3[[#This Row],[使用材料]],[1]材料清单!$D$2:$N$996,4,0),"") -> 1090 | H20: =IFERROR(VLOOKUP(表1_3[[#This Row],[使用材料]],[1]材料清单!$D$2:$N$996,5,0),"") -> 200 | I20: 150 | J20: =IFERROR(Q20/H20,"") -> 0.12029062 | K20: =IFERROR(J20/M20,"") -> 0.016553756 | L20: =(M20-INT(M20))*I20 -> 40 | M20: =G20/I20 -> 7.2666667 | N20: 273 | O20: 16 | P20: 1410 | Q20: =P20*(N20/1000)/O20 -> 24.058125 | R20: =Q20*I20/1000*1.05 -> 3.7891547 | U20: =IFERROR((VLOOKUP(F20,[1]材料清单!D19:K2013,6,0)),"") -> 4.8
F21: 积水5240PSB | G21: =IFERROR(VLOOKUP(表1_3[[#This Row],[使用材料]],[1]材料清单!$D$2:$N$996,4,0),"") -> 980 | H21: =IFERROR(VLOOKUP(表1_3[[#This Row],[使用材料]],[1]材料清单!$D$2:$N$996,5,0),"") -> 50 | I21: 145 | J21: =IFERROR(Q21/H21,"") -> 0.4811625 | K21: =IFERROR(J21/M21,"") -> 0.071192411 | L21: =(M21-INT(M21))*I21 -> 110 | M21: =G21/I21 -> 6.7586207 | N21: 273 | O21: 16 | P21: 1410 | Q21: =P21*(N21/1000)/O21 -> 24.058125 | R21: =Q21*I21/1000*1.05 -> 3.6628495 | U21: =IFERROR((VLOOKUP(F21,[1]材料清单!D20:K2014,6,0)),"") -> 190
F22: 0.075mm 透明离型膜3-5g | G22: =IFERROR(VLOOKUP(表1_3[[#This Row],[使用材料]],[1]材料清单!$D$2:$N$996,4,0),"") -> 1090 | H22: =IFERROR(VLOOKUP(表1_3[[#This Row],[使用材料]],[1]材料清单!$D$2:$N$996,5,0),"") -> 200 | I22: 150 | J22: =IFERROR(Q22/H22,"") -> 0.12029062 | K22: =IFERROR(J22/M22,"") -> 0.016553756 | L22: =(M22-INT(M22))*I22 -> 40 | M22: =G22/I22 -> 7.2666667 | N22: 273 | O22: 16 | P22: 1410 | Q22: =P22*(N22/1000)/O22 -> 24.058125 | R22: =Q22*I22/1000*1.05 -> 3.7891547 | U22: =IFERROR((VLOOKUP(F22,[1]材料清单!D21:K2015,6,0)),"") -> 3.5
C24: 华云 | D24: 10-01-1822A-泡棉 | E24: 10-01-1822A-泡棉 | F24: 积水5220PSB | G24: 1000 | H24: =IFERROR(VLOOKUP(表1_3[[#This Row],[使用材料]],[1]材料清单!$D$2:$N$996,5,0),"") -> 50 | I24: 125 | J24: =IFERROR(Q24/H24,"") -> 2.952 | K24: =IFERROR(J24/M24,"") -> 0.369 | L24: =(M24-INT(M24))*I24 -> 0 | M24: =G24/I24 -> 8 | N24: 18 | O24: 1 | P24: 8200 | Q24: =P24*(N24/1000)/O24 -> 147.6 | R24: =Q24*I24/1000*1.05 -> 19.3725 | S24: SD231111-001A02A-01A-18 | U24: =IFERROR((VLOOKUP(F24,[1]材料清单!D22:K2016,6,0)),"") -> 190
F25: 0.1蓝色离型膜30-40G | G25: =IFERROR(VLOOKUP(表1_3[[#This Row],[使用材料]],[1]材料清单!$D$2:$N$996,4,0),"") -> 1090 | H25: =IFERROR(VLOOKUP(表1_3[[#This Row],[使用材料]],[1]材料清单!$D$2:$N$996,5,0),"") -> 200 | I25: 132 | J25: =IFERROR(Q25/H25,"") -> 0.738 | K25: =IFERROR(J25/M25,"") -> 0.089372477 | L25: =(M25-INT(M25))*I25 -> 34 | M25: =G25/I25 -> 8.2575758 | N25: 18 | O25: 1 | P25: =P24 -> 8200 | Q25: =P25*(N25/1000)/O25 -> 147.6 | R25: =Q25*I25/1000*1.05 -> 20.45736 | U25: =IFERROR((VLOOKUP(F25,[1]材料清单!D23:K2017,6,0)),"") -> 4.8
F26: 0.075mm 透明离型膜3-5g | G26: =IFERROR(VLOOKUP(表1_3[[#This Row],[使用材料]],[1]材料清单!$D$2:$N$996,4,0),"") -> 1090 | H26: =IFERROR(VLOOKUP(表1_3[[#This Row],[使用材料]],[1]材料清单!$D$2:$N$996,5,0),"") -> 200 | I26: 150 | J26: =IFERROR(Q26/H26,"") -> 0.738 | K26: =IFERROR(J26/M26,"") -> 0.10155963 | L26: =(M26-INT(M26))*I26 -> 40 | M26: =G26/I26 -> 7.2666667 | N26: 18 | O26: 1 | P26: 8200 | Q26: =P26*(N26/1000)/O26 -> 147.6 | R26: =Q26*I26/1000*1.05 -> 23.247 | U26: =IFERROR((VLOOKUP(F26,[1]材料清单!D24:K2018,6,0)),"") -> 3.5
C28: 华云 | D28: 10-04-1822A-泡棉 | E28: 10-04-1822A-泡棉 | F28: 积水5220PSB | G28: 1000 | H28: =IFERROR(VLOOKUP(表1_3[[#This Row],[使用材料]],[1]材料清单!$D$2:$N$996,5,0),"") -> 50 | I28: 125 | J28: =IFERROR(Q28/H28,"") -> 1.9812 | K28: =IFERROR(J28/M28,"") -> 0.24765 | L28: =(M28-INT(M28))*I28 -> 0 | M28: =G28/I28 -> 8 | N28: 12.7 | O28: 1 | P28: 7800 | Q28: =P28*(N28/1000)/O28 -> 99.06 | R28: =Q28*I28/1000*1.05 -> 13.001625 | U28: =IFERROR((VLOOKUP(F28,[1]材料清单!D25:K2019,6,0)),"") -> 190
F29: 0.1蓝色离型膜30-40G | G29: =IFERROR(VLOOKUP(表1_3[[#This Row],[使用材料]],[1]材料清单!$D$2:$N$996,4,0),"") -> 1090 | H29: =IFERROR(VLOOKUP(表1_3[[#This Row],[使用材料]],[1]材料清单!$D$2:$N$996,5,0),"") -> 200 | I29: 132 | J29: =IFERROR(Q29/H29,"") -> 0.4953 | K29: =IFERROR(J29/M29,"") -> 0.059981284 | L29: =(M29-INT(M29))*I29 -> 34 | M29: =G29/I29 -> 8.2575758 | N29: 12.7 | O29: 1 | P29: =P28 -> 7800 | Q29: =P29*(N29/1000)/O29 -> 99.06 | R29: =Q29*I29/1000*1.05 -> 13.729716 | U29: =IFERROR((VLOOKUP(F29,[1]材料清单!D26:K2020,6,0)),"") -> 4.8
F30: 0.075mm 透明离型膜3-5g | G30: =IFERROR(VLOOKUP(表1_3[[#This Row],[使用材料]],[1]材料清单!$D$2:$N$996,4,0),"") -> 1090 | H30: =IFERROR(VLOOKUP(表1_3[[#This Row],[使用材料]],[1]材料清单!$D$2:$N$996,5,0),"") -> 200 | I30: 150 | J30: =IFERROR(Q30/H30,"") -> 0.4953 | K30: =IFERROR(J30/M30,"") -> 0.06816055 | L30: =(M30-INT(M30))*I30 -> 40 | M30: =G30/I30 -> 7.2666667 | N30: 12.7 | O30: 1 | P30: =P29 -> 7800 | Q30: =P30*(N30/1000)/O30 -> 99.06 | R30: =Q30*I30/1000*1.05 -> 15.60195 | U30: =IFERROR((VLOOKUP(F30,[1]材料清单!D27:K2021,6,0)),"") -> 3.5
C31: 华云 | D31: 10-02-1822A-泡棉 | E31: 10-02-1822A-泡棉 | F31: 积水5220PSB | G31: =IFERROR(VLOOKUP(表1_3[[#This Row],[使用材料]],[1]材料清单!$D$2:$N$996,4,0),"") -> 980 | H31: =IFERROR(VLOOKUP(表1_3[[#This Row],[使用材料]],[1]材料清单!$D$2:$N$996,5,0),"") -> 50 | I31: 180 | J31: =IFERROR(Q31/H31,"") -> 0.759 | K31: =IFERROR(J31/M31,"") -> 0.13940816 | L31: =(M31-INT(M31))*I31 -> 80 | M31: =G31/I31 -> 5.4444444 | N31: 5.5 | O31: 1 | P31: 6900 | Q31: =P31*(N31/1000)/O31 -> 37.95 | R31: =Q31*I31/1000*1.05 -> 7.17255 | U31: =IFERROR((VLOOKUP(F31,[1]材料清单!D28:K2022,6,0)),"") -> 190
F32: 0.1蓝色离型膜30-40G | G32: =IFERROR(VLOOKUP(表1_3[[#This Row],[使用材料]],[1]材料清单!$D$2:$N$996,4,0),"") -> 1090 | H32: =IFERROR(VLOOKUP(表1_3[[#This Row],[使用材料]],[1]材料清单!$D$2:$N$996,5,0),"") -> 200 | I32: 200 | J32: =IFERROR(Q32/H32,"") -> 0.18975 | K32: =IFERROR(J32/M32,"") -> 0.034816514 | L32: =(M32-INT(M32))*I32 -> 90 | M32: =G32/I32 -> 5.45 | N32: =N31 -> 5.5 | O32: 1 | P32: 6900 | Q32: =P32*(N32/1000)/O32 -> 37.95 | R32: =Q32*I32/1000*1.05 -> 7.9695 | U32: =IFERROR((VLOOKUP(F32,[1]材料清单!D29:K2023,6,0)),"") -> 4.8
F33: 0.075mm 透明离型膜3-5g | G33: =IFERROR(VLOOKUP(表1_3[[#This Row],[使用材料]],[1]材料清单!$D$2:$N$996,4,0),"") -> 1090 | H33: =IFERROR(VLOOKUP(表1_3[[#This Row],[使用材料]],[1]材料清单!$D$2:$N$996,5,0),"") -> 200 | I33: 200 | J33: =IFERROR(Q33/H33,"") -> 0.18975 | K33: =IFERROR(J33/M33,"") -> 0.034816514 | L33: =(M33-INT(M33))*I33 -> 90 | M33: =G33/I33 -> 5.45 | N33: =N32 -> 5.5 | O33: 1 | P33: 6900 | Q33: =P33*(N33/1000)/O33 -> 37.95 | R33: =Q33*I33/1000*1.05 -> 7.9695 | U33: =IFERROR((VLOOKUP(F33,[1]材料清单!D30:K2024,6,0)),"") -> 3.5
C34: 华云 | D34: 10-03-1822A-泡棉 | E34: 10-03-1822A-泡棉 | F34: 积水5220PSB | G34: =IFERROR(VLOOKUP(表1_3[[#This Row],[使用材料]],[1]材料清单!$D$2:$N$996,4,0),"") -> 980 | H34: =IFERROR(VLOOKUP(表1_3[[#This Row],[使用材料]],[1]材料清单!$D$2:$N$996,5,0),"") -> 50 | I34: 180 | J34: =IFERROR(Q34/H34,"") -> 0.759 | K34: =IFERROR(J34/M34,"") -> 0.13940816 | L34: =(M34-INT(M34))*I34 -> 80 | M34: =G34/I34 -> 5.4444444 | N34: =N33 -> 5.5 | O34: 1 | P34: 6900 | Q34: =P34*(N34/1000)/O34 -> 37.95 | R34: =Q34*I34/1000*1.05 -> 7.17255 | U34: =IFERROR((VLOOKUP(F34,[1]材料清单!D31:K2025,6,0)),"") -> 190
F35: 0.1蓝色离型膜30-40G | G35: =IFERROR(VLOOKUP(表1_3[[#This Row],[使用材料]],[1]材料清单!$D$2:$N$996,4,0),"") -> 1090 | H35: =IFERROR(VLOOKUP(表1_3[[#This Row],[使用材料]],[1]材料清单!$D$2:$N$996,5,0),"") -> 200 | I35: 200 | J35: =IFERROR(Q35/H35,"") -> 0.18975 | K35: =IFERROR(J35/M35,"") -> 0.034816514 | L35: =(M35-INT(M35))*I35 -> 90 | M35: =G35/I35 -> 5.45 | N35: =N34 -> 5.5 | O35: 1 | P35: 6900 | Q35: =P35*(N35/1000)/O35 -> 37.95 | R35: =Q35*I35/1000*1.05 -> 7.9695 | U35: =IFERROR((VLOOKUP(F35,[1]材料清单!D32:K2026,6,0)),"") -> 4.8
F36: 0.075mm 透明离型膜3-5g | G36: =IFERROR(VLOOKUP(表1_3[[#This Row],[使用材料]],[1]材料清单!$D$2:$N$996,4,0),"") -> 1090 | H36: =IFERROR(VLOOKUP(表1_3[[#This Row],[使用材料]],[1]材料清单!$D$2:$N$996,5,0),"") -> 200 | I36: 200 | J36: =IFERROR(Q36/H36,"") -> 0.18975 | K36: =IFERROR(J36/M36,"") -> 0.034816514 | L36: =IFERROR((M36-INT(M36))*I36,"") -> 90 | M36: =IFERROR(G36/I36,"") -> 5.45 | N36: =N35 -> 5.5 | O36: 1 | P36: 6900 | Q36: =IFERROR(P36*(N36/1000)/O36,"") -> 37.95 | R36: =IFERROR(Q36*I36/1000*1.05,"") -> 7.9695 | U36: =IFERROR((VLOOKUP(F36,[1]材料清单!D33:K2027,6,0)),"") -> 3.5
C37: 华云 | D37: 09-01-1822A-背胶 | E37: 09-01-1822A-背胶(3M GPL060灰色胶） | F37: GPL-060GF | G37: =IFERROR(VLOOKUP(表1_3[[#This Row],[使用材料]],[1]材料清单!$D$2:$N$996,4,0),"") -> 600 | H37: =IFERROR(VLOOKUP(表1_3[[#This Row],[使用材料]],[1]材料清单!$D$2:$N$996,5,0),"") -> 33 | I37: 185 | J37: =IFERROR(Q37/H37,"") -> 2.263697 | K37: =IFERROR(J37/M37,"") -> 0.69797323 | L37: =IFERROR((M37-INT(M37))*I37,"") -> 45 | M37: =IFERROR(G37/I37,"") -> 3.2432432 | N37: 9.11 | O37: 1 | P37: 8200 | Q37: =IFERROR(P37*(N37/1000)/O37,"") -> 74.702 | R37: =IFERROR(Q37*I37/1000*1.05,"") -> 14.510863 | U37: =IFERROR((VLOOKUP(F37,[1]材料清单!D34:K2028,6,0)),"") -> 123.73737
F38: 0.1蓝色离型膜30-40G | G38: =IFERROR(VLOOKUP(表1_3[[#This Row],[使用材料]],[1]材料清单!$D$2:$N$996,4,0),"") -> 1090 | H38: =IFERROR(VLOOKUP(表1_3[[#This Row],[使用材料]],[1]材料清单!$D$2:$N$996,5,0),"") -> 200 | I38: 200 | J38: =IFERROR(Q38/H38,"") -> 0.37351 | K38: =IFERROR(J38/M38,"") -> 0.068533945 | L38: =IFERROR((M38-INT(M38))*I38,"") -> 90 | M38: =IFERROR(G38/I38,"") -> 5.45 | N38: =N37 -> 9.11 | O38: 1 | P38: =P37 -> 8200 | Q38: =IFERROR(P38*(N38/1000)/O38,"") -> 74.702 | R38: =IFERROR(Q38*I38/1000*1.05,"") -> 15.68742 | U38: =IFERROR((VLOOKUP(F38,[1]材料清单!D35:K2029,6,0)),"") -> 4.8
F39: 0.075mm 透明离型膜3-5g | G39: =IFERROR(VLOOKUP(表1_3[[#This Row],[使用材料]],[1]材料清单!$D$2:$N$996,4,0),"") -> 1090 | H39: =IFERROR(VLOOKUP(表1_3[[#This Row],[使用材料]],[1]材料清单!$D$2:$N$996,5,0),"") -> 200 | I39: 200 | J39: =IFERROR(Q39/H39,"") -> 0.05466 | K39: =IFERROR(J39/M39,"") -> 0.010029358 | L39: =IFERROR((M39-INT(M39))*I39,"") -> 90 | M39: =IFERROR(G39/I39,"") -> 5.45 | N39: =N38 -> 9.11 | O39: 1 | P39: 1200 | Q39: =IFERROR(P39*(N39/1000)/O39,"") -> 10.932 | R39: =IFERROR(Q39*I39/1000*1.05,"") -> 2.29572 | U39: =IFERROR((VLOOKUP(F39,[1]材料清单!D36:K2030,6,0)),"") -> 3.5
C40: 华云 | D40: 09-02-1822A-背胶 | E40: 09-02-1822A-背胶(3M GPL060灰色胶） | F40: GPL-060GF | G40: =IFERROR(VLOOKUP(表1_3[[#This Row],[使用材料]],[1]材料清单!$D$2:$N$996,4,0),"") -> 600 | H40: =IFERROR(VLOOKUP(表1_3[[#This Row],[使用材料]],[1]材料清单!$D$2:$N$996,5,0),"") -> 33 | I40: 200 | J40: =IFERROR(Q40/H40,"") -> 1.3206667 | K40: =IFERROR(J40/M40,"") -> 0.44022222 | L40: =IFERROR((M40-INT(M40))*I40,"") -> 0 | M40: =IFERROR(G40/I40,"") -> 3 | N40: 5.66 | O40: 1 | P40: 7700 | Q40: =IFERROR(P40*(N40/1000)/O40,"") -> 43.582 | R40: =IFERROR(Q40*I40/1000*1.05,"") -> 9.15222 | U40: =IFERROR((VLOOKUP(F40,[1]材料清单!D37:K2031,6,0)),"") -> 123.73737
F41: 0.1蓝色离型膜30-40G | G41: =IFERROR(VLOOKUP(表1_3[[#This Row],[使用材料]],[1]材料清单!$D$2:$N$996,4,0),"") -> 1090 | H41: =IFERROR(VLOOKUP(表1_3[[#This Row],[使用材料]],[1]材料清单!$D$2:$N$996,5,0),"") -> 200 | I41: 210 | J41: =IFERROR(Q41/H41,"") -> 0.21791 | K41: =IFERROR(J41/M41,"") -> 0.041982661 | L41: =IFERROR((M41-INT(M41))*I41,"") -> 40 | M41: =IFERROR(G41/I41,"") -> 5.1904762 | N41: =N40 -> 5.66 | O41: 1 | P41: =P40 -> 7700 | Q41: =IFERROR(P41*(N41/1000)/O41,"") -> 43.582 | R41: =IFERROR(Q41*I41/1000*1.05,"") -> 9.609831 | U41: =IFERROR((VLOOKUP(F41,[1]材料清单!D38:K2032,6,0)),"") -> 4.8
F42: 0.075mm 透明离型膜3-5g | G42: =IFERROR(VLOOKUP(表1_3[[#This Row],[使用材料]],[1]材料清单!$D$2:$N$996,4,0),"") -> 1090 | H42: =IFERROR(VLOOKUP(表1_3[[#This Row],[使用材料]],[1]材料清单!$D$2:$N$996,5,0),"") -> 200 | I42: 210 | J42: =IFERROR(Q42/H42,"") -> 0.21791 | K42: =IFERROR(J42/M42,"") -> 0.041982661 | L42: =IFERROR((M42-INT(M42))*I42,"") -> 40 | M42: =IFERROR(G42/I42,"") -> 5.1904762 | N42: =N41 -> 5.66 | O42: 1 | P42: =P41 -> 7700 | Q42: =IFERROR(P42*(N42/1000)/O42,"") -> 43.582 | R42: =IFERROR(Q42*I42/1000*1.05,"") -> 9.609831 | U42: =IFERROR((VLOOKUP(F42,[1]材料清单!D39:K2033,6,0)),"") -> 3.5
C43: 华云 | D43: 09-01-2003A0-背胶 | E43: 09-01-2003A0-背胶（5240PSB) | F43: 积水5220PSB | G43: =IFERROR(VLOOKUP(表1_3[[#This Row],[使用材料]],[1]材料清单!$D$2:$N$996,4,0),"") -> 980 | H43: =IFERROR(VLOOKUP(表1_3[[#This Row],[使用材料]],[1]材料清单!$D$2:$N$996,5,0),"") -> 50 | I43: 171 | J43: =IFERROR(Q43/H43,"") -> 4.84 | K43: =IFERROR(J43/M43,"") -> 0.84453061 | L43: =IFERROR((M43-INT(M43))*I43,"") -> 125 | M43: =IFERROR(G43/I43,"") -> 5.7309942 | N43: 121 | O43: 1 | P43: 2000 | Q43: =IFERROR(P43*(N43/1000)/O43,"") -> 242 | R43: =IFERROR(Q43*I43/1000*1.05,"") -> 43.4511 | U43: =IFERROR((VLOOKUP(F43,[1]材料清单!D40:K2034,6,0)),"") -> 190
...
